<?xml version="1.0"?>
<robot
  name="AUBO_HRA_R">
  <dh_type type="modified"/>
  <safety_para singularity_consistent="0.02 0.01 10 0.2 0.045 10"/>
  <friction_coeff value="0.5"/>
  <link
    name="link0">
    <inertial>
      <origin
        xyz="-0.000004 0.000007 -0.015226"
        rpy="0 0 0" />
      <mass
        value="1.065000" />
      <inertia
        ixx="0.000856" ixy="-0.000000" ixz="0.000000" iyy="0.000856" iyz="-0.000000" izz="0.000677" />
    </inertial>
    <visual>
      <origin
        xyz="0 0 0"
        rpy="0 0 0" />
      <geometry>
        <mesh filename="package://aubo_description/meshes/AUBO_HRA_R/visual/link0.STL" />
      </geometry>
      <material
        name="">
        <color
          rgba="0.752941176470588 0.752941176470588 0.752941176470588 1" />
      </material>
    </visual>
    <collision>
      <origin
        xyz="0 0 0"
        rpy="0 0 0" />
      <geometry>
        <mesh filename="package://aubo_description/meshes/AUBO_HRA_R/collision/link0.STL" />
      </geometry>
    </collision>
  </link>
  <link
    name="link1">
    <inertial>
      <origin
        xyz="0.000216 0.003370 -0.030567"
        rpy="0 0 0" />
      <mass
        value="0.254000" />
      <inertia
        ixx="0.000616" ixy="0.000002" ixz="0.000001" iyy="0.000324" iyz="0.000001" izz="0.000586" />
    </inertial>
    <visual>
      <origin
        xyz="0 0 0"
        rpy="0 0 0" />
      <geometry>
        <mesh filename="package://aubo_description/meshes/AUBO_HRA_R/visual/link1.STL" />
      </geometry>
      <material
        name="">
        <color
          rgba="0.752941176470588 0.752941176470588 0.752941176470588 1" />
      </material>
    </visual>
    <collision>
      <origin
        xyz="0 0 0"
        rpy="0 0 0" />
      <geometry>
        <mesh filename="package://aubo_description/meshes/AUBO_HRA_R/collision/link1.STL" />
      </geometry>
    </collision>
  </link>
  <joint
    name="joint1"
    type="revolute">
    <origin
      xyz="0 0 0.0767"
      rpy="0 0 0" />
    <parent
      link="link0" />
    <child
      link="link1" />
    <axis
      xyz="0 0 1" />
    <limit lower="-0.785398163397448" upper="3.14159265358979" effort="40" start_stop="82" velocity="3.14159265358979" />
    <property inertia="1.24" damping="0" stiffness="0" offset="0" motor_constant="5.31" ratio="100" protect_max_torque="0" equa_inertia="0" />
   <dynamics damping="1.1" friction="1.5"/>
</joint>
  <link
    name="link2">
    <inertial>
      <origin
        xyz="0.000001 0.000686 0.007925"
        rpy="0 0 0" />
      <mass
        value="1.258000" />
      <inertia
        ixx="0.001183" ixy="-0.000000" ixz="0.000000" iyy="0.001157" iyz="0.000006" izz="0.000996" />
    </inertial>
    <visual>
      <origin
        xyz="0 0 0"
        rpy="0 0 0" />
      <geometry>
        <mesh filename="package://aubo_description/meshes/AUBO_HRA_R/visual/link2.STL" />
      </geometry>
      <material
        name="">
        <color
          rgba="0.75294 0.75294 0.75294 1" />
      </material>
    </visual>
    <collision>
      <origin
        xyz="0 0 0"
        rpy="0 0 0" />
      <geometry>
        <mesh filename="package://aubo_description/meshes/AUBO_HRA_R/collision/link2.STL" />
      </geometry>
    </collision>
  </link>
  <joint
    name="joint2"
    type="revolute">
    <origin
      xyz="0 0 0.0"
      rpy="-1.5707963267948966192313216916398 -1.5707963267948966192313216916398 0" />
    <parent
      link="link1" />
    <child
      link="link2" />
    <axis
      xyz="0 0 1" />
    <limit lower="0" upper="1.74532925199433" effort="40" start_stop="82" velocity="3.14159265358979" />
    <property inertia="1.24" damping="0" stiffness="0" offset="0" motor_constant="5.31" ratio="100" protect_max_torque="0" equa_inertia="0" />
   <dynamics damping="1.1" friction="1.5"/>
</joint>
  <link
    name="link3">
    <inertial>
      <origin
        xyz="0.000259 -0.004337 -0.082770"
        rpy="0 0 0" />
      <mass
        value="1.810000" />
      <inertia
        ixx="0.013999" ixy="-0.000002" ixz="-0.000017" iyy="0.013812" iyz="0.000650" izz="0.001277" />
    </inertial>
    <visual>
      <origin
        xyz="0 0 0"
        rpy="0 0 0" />
      <geometry>
        <mesh filename="package://aubo_description/meshes/AUBO_HRA_R/visual/link3.STL" />
      </geometry>
      <material
        name="">
        <color
          rgba="0.752941176470588 0.752941176470588 0.752941176470588 1" />
      </material>
    </visual>
    <collision>
      <origin
        xyz="0 0 0"
        rpy="0 0 0" />
      <geometry>
        <mesh filename="package://aubo_description/meshes/AUBO_HRA_R/collision/link3.STL" />
      </geometry>
    </collision>
  </link>
  <joint
    name="joint3"
    type="revolute">
    <origin
      xyz="0 0.253 0"
      rpy="-1.5707963267948966192313216916398 0 0" />
    <parent
      link="link2" />
    <child
      link="link3" />
    <axis
      xyz="0 0 1" />
    <limit lower="-2.26892802759263" upper="2.26892802759263" effort="22" start_stop="42" velocity="4.18879020478639" />
    <property inertia="0.2" damping="0" stiffness="0" offset="0" motor_constant="4.5" ratio="100" protect_max_torque="0" equa_inertia="0" />
   <dynamics damping="1.1" friction="1.5"/>
</joint>
  <link
    name="link4">
    <inertial>
      <origin
        xyz="0.002858 0.021411 0.004644"
        rpy="0 0 0" />
      <mass
        value="0.155000" />
      <inertia
        ixx="0.000300" ixy="-0.000005" ixz="0.000002" iyy="0.000263" iyz="0.000003" izz="0.000157" />
    </inertial>
    <visual>
      <origin
        xyz="0 0 0"
        rpy="0 0 0" />
      <geometry>
        <mesh filename="package://aubo_description/meshes/AUBO_HRA_R/visual/link4.STL" />
      </geometry>
      <material
        name="">
        <color
          rgba="0.75294 0.75294 0.75294 1" />
      </material>
    </visual>
    <collision>
      <origin
        xyz="0 0 0"
        rpy="0 0 0" />
      <geometry>
        <mesh filename="package://aubo_description/meshes/AUBO_HRA_R/collision/link4.STL" />
      </geometry>
    </collision>
  </link>
  <joint
    name="joint4"
    type="revolute">
    <origin
      xyz="0 0 0"
      rpy="1.5707963267948966192313216916398 0 0" />
    <parent
      link="link3" />
    <child
      link="link4" />
    <axis
      xyz="0 0 1" />
    <limit lower="-2.26892802759263" upper="0" effort="22" start_stop="42" velocity="4.18879020478639" />
    <property inertia="0.2" damping="0" stiffness="0" offset="0" motor_constant="4.5" ratio="100" protect_max_torque="0" equa_inertia="0" />
   <dynamics damping="1.1" friction="1.5"/>
</joint>
  <link
    name="link5">
    <inertial>
      <origin
        xyz="-0.000993 -0.004328 -0.106584"
        rpy="0 0 0" />
      <mass
        value="1.191000" />
      <inertia
        ixx="0.002945" ixy="-0.000053" ixz="0.000071" iyy="0.002574" iyz="0.000245" izz="0.000888" />
    </inertial>
    <visual>
      <origin
        xyz="0 0 0"
        rpy="0 0 0" />
      <geometry>
        <mesh filename="package://aubo_description/meshes/AUBO_HRA_R/visual/link5.STL" />
      </geometry>
      <material
        name="">
        <color
          rgba="0.752941176470588 0.752941176470588 0.752941176470588 1" />
      </material>
    </visual>
    <collision>
      <origin
        xyz="0 0 0"
        rpy="0 0 0" />
      <geometry>
        <mesh filename="package://aubo_description/meshes/AUBO_HRA_R/collision/link5.STL" />
      </geometry>
    </collision>
  </link>
  <joint
    name="joint5"
    type="revolute">
    <origin
      xyz="0 0.2355 0"
      rpy="-1.5707963267948966192313216916398 0 0" />
    <parent
      link="link4" />
    <child
      link="link5" />
    <axis
      xyz="0 0 1" />
    <limit lower="-2.26892802759263" upper="2.26892802759263" effort="8" start_stop="15" velocity="3.14159265358979" />
    <property inertia="0.085" damping="0" stiffness="0" offset="0" motor_constant="4.63" ratio="100" protect_max_torque="0" equa_inertia="0" />
   <dynamics damping="1.1" friction="1.5"/>
</joint>
  <link
    name="link6">
    <inertial>
      <origin
        xyz="0.000000 0.003777 0.001004"
        rpy="0 0 0" />
      <mass
        value="0.519000" />
      <inertia
        ixx="0.000282" ixy="-0.000000" ixz="-0.000000" iyy="0.000213" iyz="-0.000009" izz="0.000254" />
    </inertial>
    <visual>
      <origin
        xyz="0 0 0"
        rpy="0 0 0" />
      <geometry>
        <mesh filename="package://aubo_description/meshes/AUBO_HRA_R/visual/link6.STL" />
      </geometry>
      <material
        name="">
        <color
          rgba="0.75294 0.75294 0.75294 1" />
      </material>
    </visual>
    <collision>
      <origin
        xyz="0 0 0"
        rpy="0 0 0" />
      <geometry>
        <mesh filename="package://aubo_description/meshes/AUBO_HRA_R/collision/link6.STL" />
      </geometry>
    </collision>
  </link>
  <joint
    name="joint6"
    type="revolute">
    <origin
      xyz="0 0 0"
      rpy="1.5707963267948966192313216916398 -1.5707963267948966192313216916398 0" />
    <parent
      link="link5" />
    <child
      link="link6" />
    <axis
      xyz="0 0 1" />
    <limit lower="-1.30899693899575" upper="1.30899693899575" effort="8" start_stop="15" velocity="3.14159265358979" />
    <property inertia="0.085" damping="0" stiffness="0" offset="0" motor_constant="4.63" ratio="100" protect_max_torque="0" equa_inertia="0" />
   <dynamics damping="1.1" friction="1.5"/>
</joint>
  <link
    name="link7">
    <inertial>
      <origin
        xyz="0.212000 -0.052633 0.013209"
        rpy="0 0 0" />
      <mass
        value="0.212000" />
      <inertia
        ixx="0.000209" ixy="-0.000000" ixz="-0.000000" iyy="0.000112" iyz="-0.000060" izz="0.000181" />
    </inertial>
    <visual>
      <origin
        xyz="0 0 0"
        rpy="0 0 0" />
      <geometry>
        <mesh filename="package://aubo_description/meshes/AUBO_HRA_R/visual/link7.STL" />
      </geometry>
      <material
        name="">
        <color
          rgba="0.75294 0.75294 0.75294 1" />
      </material>
    </visual>
    <collision>
      <origin
        xyz="0 0 0"
        rpy="0 0 0" />
      <geometry>
        <mesh filename="package://aubo_description/meshes/AUBO_HRA_R/collision/link7.STL" />
      </geometry>
    </collision>
  </link>
  <joint
    name="joint7"
    type="revolute">
    <origin
      xyz="0 0 0"
      rpy="1.5707963267948966192313216916398 -1.5707963267948966192313216916398 0" />
    <parent
      link="link6" />
    <child
      link="link7" />
    <axis
      xyz="0 0 1" />
    <limit lower="-1.30899693899575" upper="1.30899693899575" effort="8" start_stop="15" velocity="3.14159265358979" />
    <property inertia="0.085" damping="0" stiffness="0" offset="0" motor_constant="4.63" ratio="100" protect_max_torque="0" equa_inertia="0" />
   <dynamics damping="1.1" friction="1.5"/>
</joint>
  <link name="flange"/>
  <joint name="flange" type="fixed">
    <origin rpy="1.5707963267948966192313216916398 0 0" xyz="0 -0.084 0"/>
    <parent link="link7"/>
    <child link="flange"/>
   <dynamics damping="1.1" friction="1.5"/>
</joint>

<link name="world" />

  <joint name="world_joint" type="fixed">
    <parent link="world" />
    <child link = "link0" />
    <origin xyz="0.0 0.0 0.0" rpy="0.0 0.0 0.0" />
   <dynamics damping="1.1" friction="1.5"/>
</joint>
</robot>
