<?xml version="1.0" encoding="utf-8"?>
<robot name="aearm">
  <link name="base_link"/>

  <joint
    name="left_fixed_joint"
    type="fixed">
    <origin
      xyz="0 0.14632 0.414"
      rpy="-1.308997 0 0" />
    <parent
      link="base_link" />
    <child
      link="left_base_link" />
    <axis
      xyz="0 1 0" />
  </joint>
  <!-- <joint name="base_right_joint" type="fixed">
    <origin rpy="0 0 0" xyz="0 0.2 0.5"/>
    <parent link="base_link"/>
    <child link="right_base_link"/>
  </joint> -->
  <!-- left arm -->
  <link name="left_base_link">
    <inertial>
      <origin rpy="0 0 0" xyz="-0.00076435 -6.5733E-05 0.053673"/>
      <mass value="1.000918"/>
      <inertia ixx="0.000829" ixy="0.000001" ixz="0.000034" iyy="0.000843" iyz="0.000003" izz="0.000621"/>
    </inertial>
    <visual>
      <origin rpy="0 0 0" xyz="0 0 0"/>
      <geometry>
        <mesh filename="package://arm_kinematics_solver/meshes/base_link.STL"/>
      </geometry>
      <material name="">
        <color rgba="0.79216 0.81961 0.93333 1"/>
      </material>
    </visual>
    <collision>
      <origin rpy="0 0 0" xyz="0 0 0"/>
      <geometry>
        <mesh filename="package://arm_kinematics_solver/meshes/base_link.STL"/>
      </geometry>
    </collision>
  </link>
  <link name="left_Link1">
    <inertial>
      <origin rpy="0 0 0" xyz="-5.2554E-05 -0.0053442 -0.0082759"/>
      <mass value="1.301479"/>
      <inertia ixx="0.001955" ixy="-0.000003" ixz="-0.000002" iyy="0.001633" iyz="-0.000034" izz="0.001269"/>
    </inertial>
    <visual>
      <origin rpy="0 0 0" xyz="0 0 0"/>
      <geometry>
        <mesh filename="package://arm_kinematics_solver/meshes/Link1.STL"/>
      </geometry>
      <material name="">
        <color rgba="0.79216 0.81961 0.93333 1"/>
      </material>
    </visual>
    <collision>
      <origin rpy="0 0 0" xyz="0 0 0"/>
      <geometry>
        <mesh filename="package://arm_kinematics_solver/meshes/Link1.STL"/>
      </geometry>
    </collision>
  </link>
  <joint name="left_joint1" type="revolute">
    <origin rpy="0 0 0" xyz="0 0 0.182"/>
    <parent link="left_base_link"/>
    <child link="left_Link1"/>
    <axis xyz="0 0 1"/>
    <limit effort="0" lower="-3.1415926" upper="3.1415926" velocity="0"/>
  </joint>
  <link name="left_Link2">
    <inertial>
      <origin rpy="0 0 0" xyz="0.00025764 -0.094316 0.00044678"/>
      <mass value="1.191673"/>
      <inertia ixx="0.003751" ixy="0.000005" ixz="0.000003" iyy="0.001170" iyz="0.000117" izz="0.003283"/>
    </inertial>
    <visual>
      <origin rpy="0 0 0" xyz="0 0 0"/>
      <geometry>
        <mesh filename="package://arm_kinematics_solver/meshes/Link2.STL"/>
      </geometry>
      <material name="">
        <color rgba="0.79216 0.81961 0.93333 1"/>
      </material>
    </visual>
    <collision>
      <origin rpy="0 0 0" xyz="0 0 0"/>
      <geometry>
        <mesh filename="package://arm_kinematics_solver/meshes/Link2.STL"/>
      </geometry>
    </collision>
  </link>
  <joint name="left_joint2" type="revolute">
    <origin rpy="-1.5707963267948966 0 0" xyz="0 0 0"/>
    <parent link="left_Link1"/>
    <child link="left_Link2"/>
    <axis xyz="0 0 1"/>
    <limit effort="0" lower="-2.18" upper="2.18" velocity="0"/>
  </joint>
  <link name="left_Link3">
    <inertial>
      <origin rpy="0 0 0" xyz="0.00031625 -0.0039156 -0.012819"/>
      <mass value="1.004294"/>
      <inertia ixx="0.001754" ixy="0.000012" ixz="0.000008" iyy="0.001475" iyz="-0.000039" izz="0.000839"/>
    </inertial>
    <visual>
      <origin rpy="0 0 0" xyz="0 0 0"/>
      <geometry>
        <mesh filename="package://arm_kinematics_solver/meshes/Link3.STL"/>
      </geometry>
      <material name="">
        <color rgba="0.79216 0.81961 0.93333 1"/>
      </material>
    </visual>
    <collision>
      <origin rpy="0 0 0" xyz="0 0 0"/>
      <geometry>
        <mesh filename="package://arm_kinematics_solver/meshes/Link3.STL"/>
      </geometry>
    </collision>
  </link>
  <joint name="left_joint3" type="revolute">
    <origin rpy="1.5707963267948966 0 0" xyz="0 -0.276 0"/>
    <parent link="left_Link2"/>
    <child link="left_Link3"/>
    <axis xyz="0 0 1"/>
    <limit effort="0" lower="-3.1415926" upper="3.1415926" velocity="0"/>
  </joint>
  <link name="left_Link4">
    <inertial>
      <origin rpy="0 0 0" xyz="9.892E-06 -0.075751 3.1247E-05"/>
      <mass value="0.725811"/>
      <inertia ixx="0.001959" ixy="-0.000001" ixz="0.000000" iyy="0.000660" iyz="0.000072" izz="0.001613"/>
    </inertial>
    <visual>
      <origin rpy="0 0 0" xyz="0 0 0"/>
      <geometry>
        <mesh filename="package://arm_kinematics_solver/meshes/Link4.STL"/>
      </geometry>
      <material name="">
        <color rgba="0.79216 0.81961 0.93333 1"/>
      </material>
    </visual>
    <collision>
      <origin rpy="0 0 0" xyz="0 0 0"/>
      <geometry>
        <mesh filename="package://arm_kinematics_solver/meshes/Link4.STL"/>
      </geometry>
    </collision>
  </link>
  <joint name="left_joint4" type="revolute">
    <origin rpy="-1.5707963267948966 0 0" xyz="0 0 0"/>
    <parent link="left_Link3"/>
    <child link="left_Link4"/>
    <axis xyz="0 0 1"/>
    <limit effort="0" lower="-2.14" upper="2.14" velocity="0"/>
  </joint>
  <link name="left_Link5">
    <inertial>
      <origin rpy="0 0 0" xyz="-3.8461E-06 0.0019832 -0.076384"/>
      <mass value="0.729280"/>
      <inertia ixx="0.001311" ixy="0.000000" ixz="0.000000" iyy="0.000991" iyz="0.000041" izz="0.000605"/>
    </inertial>
    <visual>
      <origin rpy="0 0 0" xyz="0 0 0"/>
      <geometry>
        <mesh filename="package://arm_kinematics_solver/meshes/Link5.STL"/>
      </geometry>
      <material name="">
        <color rgba="0.79216 0.81961 0.93333 1"/>
      </material>
    </visual>
    <collision>
      <origin rpy="0 0 0" xyz="0 0 0"/>
      <geometry>
        <mesh filename="package://arm_kinematics_solver/meshes/Link5.STL"/>
      </geometry>
    </collision>
  </link>
  <joint name="left_joint5" type="revolute">
    <origin rpy="1.5707963267948966 0 0" xyz="0 -0.28 0"/>
    <parent link="left_Link4"/>
    <child link="left_Link5"/>
    <axis xyz="0 0 1"/>
    <limit effort="0" lower="-3.1415926" upper="3.1415926" velocity="0"/>
  </joint>
  <link name="left_Link6">
    <inertial>
      <origin rpy="0 0 0" xyz="-1.8651E-05 -0.0033108 -0.0014235"/>
      <mass value="0.476825"/>
      <inertia ixx="0.000271" ixy="0.000000" ixz="-0.000003" iyy="0.000199" iyz="-0.000003" izz="0.000234"/>
    </inertial>
    <visual>
      <origin rpy="0 0 0" xyz="0 0 0"/>
      <geometry>
        <mesh filename="package://arm_kinematics_solver/meshes/Link6.STL"/>
      </geometry>
      <material name="">
        <color rgba="0.79216 0.81961 0.93333 1"/>
      </material>
    </visual>
    <collision>
      <origin rpy="0 0 0" xyz="0 0 0"/>
      <geometry>
        <mesh filename="package://arm_kinematics_solver/meshes/Link6.STL"/>
      </geometry>
    </collision>
  </link>
  <joint name="left_joint6" type="revolute">
    <origin rpy="-1.5707963267948966 0 0" xyz="0 0 0"/>
    <parent link="left_Link5"/>
    <child link="left_Link6"/>
    <axis xyz="0 0 1"/>
    <limit effort="0" lower="-1.57" upper="1.57" velocity="0"/>
  </joint>
  <link name="left_Link7">
    <inertial>
      <origin rpy="0 0 0" xyz="-1.3476E-07 -9.8969E-08 -0.0077909"/>
      <mass value="0.035040"/>
      <inertia ixx="0.000011" ixy="0.000000" ixz="0.000000" iyy="0.000011" iyz="0.000000" izz="0.000020"/>
    </inertial>
    <visual>
      <origin rpy="0 0 0" xyz="0 0 0"/>
      <geometry>
        <mesh filename="package://arm_kinematics_solver/meshes/Link7.STL"/>
      </geometry>
      <material name="">
        <color rgba="0.79216 0.81961 0.93333 1"/>
      </material>
    </visual>
    <collision>
      <origin rpy="0 0 0" xyz="0 0 0"/>
      <geometry>
        <mesh filename="package://arm_kinematics_solver/meshes/Link7.STL"/>
      </geometry>
    </collision>
  </link>
  <joint name="left_joint7" type="revolute">
    <origin rpy="1.5707963267948966 0 0" xyz="0 -0.044 0"/>
    <parent link="left_Link6"/>
    <child link="left_Link7"/>
    <axis xyz="0 0 1"/>
    <limit effort="0" lower="-3.1415926" upper="3.1415926" velocity="0"/>
  </joint>
  <!-- right arm -->
  <!-- <link name="right_base_link">
    <inertial>
      <origin rpy="0 0 0" xyz="-0.00076435 -6.5733E-05 0.053673"/>
      <mass value="1.000918"/>
      <inertia ixx="0.000829" ixy="0.000001" ixz="0.000034" iyy="0.000843" iyz="0.000003" izz="0.000621"/>
    </inertial>
    <visual>
      <origin rpy="0 0 0" xyz="0 0 0"/>
      <geometry>
        <mesh filename="package://arm_kinematics_solver/meshes/base_link.STL"/>
      </geometry>
      <material name="">
        <color rgba="0.79216 0.81961 0.93333 1"/>
      </material>
    </visual>
    <collision>
      <origin rpy="0 0 0" xyz="0 0 0"/>
      <geometry>
        <mesh filename="package://arm_kinematics_solver/meshes/base_link.STL"/>
      </geometry>
    </collision>
  </link>
  <link name="right_Link1">
    <inertial>
      <origin rpy="0 0 0" xyz="-5.2554E-05 -0.0053442 -0.0082759"/>
      <mass value="1.301479"/>
      <inertia ixx="0.001955" ixy="-0.000003" ixz="-0.000002" iyy="0.001633" iyz="-0.000034" izz="0.001269"/>
    </inertial>
    <visual>
      <origin rpy="0 0 0" xyz="0 0 0"/>
      <geometry>
        <mesh filename="package://arm_kinematics_solver/meshes/Link1.STL"/>
      </geometry>
      <material name="">
        <color rgba="0.79216 0.81961 0.93333 1"/>
      </material>
    </visual>
    <collision>
      <origin rpy="0 0 0" xyz="0 0 0"/>
      <geometry>
        <mesh filename="package://arm_kinematics_solver/meshes/Link1.STL"/>
      </geometry>
    </collision>
  </link>
  <joint name="right_joint1" type="revolute">
    <origin rpy="0 0 0" xyz="0 0 0.182"/>
    <parent link="right_base_link"/>
    <child link="right_Link1"/>
    <axis xyz="0 0 1"/>
    <limit effort="0" lower="-3.1415926" upper="3.1415926" velocity="0"/>
  </joint>
  <link name="right_Link2">
    <inertial>
      <origin rpy="0 0 0" xyz="0.00025764 -0.094316 0.00044678"/>
      <mass value="1.191673"/>
      <inertia ixx="0.003751" ixy="0.000005" ixz="0.000003" iyy="0.001170" iyz="0.000117" izz="0.003283"/>
    </inertial>
    <visual>
      <origin rpy="0 0 0" xyz="0 0 0"/>
      <geometry>
        <mesh filename="package://arm_kinematics_solver/meshes/Link2.STL"/>
      </geometry>
      <material name="">
        <color rgba="0.79216 0.81961 0.93333 1"/>
      </material>
    </visual>
    <collision>
      <origin rpy="0 0 0" xyz="0 0 0"/>
      <geometry>
        <mesh filename="package://arm_kinematics_solver/meshes/Link2.STL"/>
      </geometry>
    </collision>
  </link>
  <joint name="right_joint2" type="revolute">
    <origin rpy="-1.5707963267948966 0 0" xyz="0 0 0"/>
    <parent link="right_Link1"/>
    <child link="right_Link2"/>
    <axis xyz="0 0 1"/>
    <limit effort="0" lower="-2.18" upper="2.18" velocity="0"/>
  </joint>
  <link name="right_Link3">
    <inertial>
      <origin rpy="0 0 0" xyz="0.00031625 -0.0039156 -0.012819"/>
      <mass value="1.004294"/>
      <inertia ixx="0.001754" ixy="0.000012" ixz="0.000008" iyy="0.001475" iyz="-0.000039" izz="0.000839"/>
    </inertial>
    <visual>
      <origin rpy="0 0 0" xyz="0 0 0"/>
      <geometry>
        <mesh filename="package://arm_kinematics_solver/meshes/Link3.STL"/>
      </geometry>
      <material name="">
        <color rgba="0.79216 0.81961 0.93333 1"/>
      </material>
    </visual>
    <collision>
      <origin rpy="0 0 0" xyz="0 0 0"/>
      <geometry>
        <mesh filename="package://arm_kinematics_solver/meshes/Link3.STL"/>
      </geometry>
    </collision>
  </link>
  <joint name="right_joint3" type="revolute">
    <origin rpy="1.5707963267948966 0 0" xyz="0 -0.276 0"/>
    <parent link="right_Link2"/>
    <child link="right_Link3"/>
    <axis xyz="0 0 1"/>
    <limit effort="0" lower="-3.1415926" upper="3.1415926" velocity="0"/>
  </joint>
  <link name="right_Link4">
    <inertial>
      <origin rpy="0 0 0" xyz="9.892E-06 -0.075751 3.1247E-05"/>
      <mass value="0.725811"/>
      <inertia ixx="0.001959" ixy="-0.000001" ixz="0.000000" iyy="0.000660" iyz="0.000072" izz="0.001613"/>
    </inertial>
    <visual>
      <origin rpy="0 0 0" xyz="0 0 0"/>
      <geometry>
        <mesh filename="package://arm_kinematics_solver/meshes/Link4.STL"/>
      </geometry>
      <material name="">
        <color rgba="0.79216 0.81961 0.93333 1"/>
      </material>
    </visual>
    <collision>
      <origin rpy="0 0 0" xyz="0 0 0"/>
      <geometry>
        <mesh filename="package://arm_kinematics_solver/meshes/Link4.STL"/>
      </geometry>
    </collision>
  </link>
  <joint name="right_joint4" type="revolute">
    <origin rpy="-1.5707963267948966 0 0" xyz="0 0 0"/>
    <parent link="right_Link3"/>
    <child link="right_Link4"/>
    <axis xyz="0 0 1"/>
    <limit effort="0" lower="-2.14" upper="2.14" velocity="0"/>
  </joint>
  <link name="right_Link5">
    <inertial>
      <origin rpy="0 0 0" xyz="-3.8461E-06 0.0019832 -0.076384"/>
      <mass value="0.729280"/>
      <inertia ixx="0.001311" ixy="0.000000" ixz="0.000000" iyy="0.000991" iyz="0.000041" izz="0.000605"/>
    </inertial>
    <visual>
      <origin rpy="0 0 0" xyz="0 0 0"/>
      <geometry>
        <mesh filename="package://arm_kinematics_solver/meshes/Link5.STL"/>
      </geometry>
      <material name="">
        <color rgba="0.79216 0.81961 0.93333 1"/>
      </material>
    </visual>
    <collision>
      <origin rpy="0 0 0" xyz="0 0 0"/>
      <geometry>
        <mesh filename="package://arm_kinematics_solver/meshes/Link5.STL"/>
      </geometry>
    </collision>
  </link>
  <joint name="right_joint5" type="revolute">
    <origin rpy="1.5707963267948966 0 0" xyz="0 -0.28 0"/>
    <parent link="right_Link4"/>
    <child link="right_Link5"/>
    <axis xyz="0 0 1"/>
    <limit effort="0" lower="-3.1415926" upper="3.1415926" velocity="0"/>
  </joint>
  <link name="right_Link6">
    <inertial>
      <origin rpy="0 0 0" xyz="-1.8651E-05 -0.0033108 -0.0014235"/>
      <mass value="0.476825"/>
      <inertia ixx="0.000271" ixy="0.000000" ixz="-0.000003" iyy="0.000199" iyz="-0.000003" izz="0.000234"/>
    </inertial>
    <visual>
      <origin rpy="0 0 0" xyz="0 0 0"/>
      <geometry>
        <mesh filename="package://arm_kinematics_solver/meshes/Link6.STL"/>
      </geometry>
      <material name="">
        <color rgba="0.79216 0.81961 0.93333 1"/>
      </material>
    </visual>
    <collision>
      <origin rpy="0 0 0" xyz="0 0 0"/>
      <geometry>
        <mesh filename="package://arm_kinematics_solver/meshes/Link6.STL"/>
      </geometry>
    </collision>
  </link>
  <joint name="right_joint6" type="revolute">
    <origin rpy="-1.5707963267948966 0 0" xyz="0 0 0"/>
    <parent link="right_Link5"/>
    <child link="right_Link6"/>
    <axis xyz="0 0 1"/>
    <limit effort="0" lower="-1.57" upper="1.57" velocity="0"/>
  </joint>
  <link name="right_Link7">
    <inertial>
      <origin rpy="0 0 0" xyz="-1.3476E-07 -9.8969E-08 -0.0077909"/>
      <mass value="0.035040"/>
      <inertia ixx="0.000011" ixy="0.000000" ixz="0.000000" iyy="0.000011" iyz="0.000000" izz="0.000020"/>
    </inertial>
    <visual>
      <origin rpy="0 0 0" xyz="0 0 0"/>
      <geometry>
        <mesh filename="package://arm_kinematics_solver/meshes/Link7.STL"/>
      </geometry>
      <material name="">
        <color rgba="0.79216 0.81961 0.93333 1"/>
      </material>
    </visual>
    <collision>
      <origin rpy="0 0 0" xyz="0 0 0"/>
      <geometry>
        <mesh filename="package://arm_kinematics_solver/meshes/Link7.STL"/>
      </geometry>
    </collision>
  </link>
  <joint name="right_joint7" type="revolute">
    <origin rpy="1.5707963267948966 0 0" xyz="0 -0.044 0"/>
    <parent link="right_Link6"/>
    <child link="right_Link7"/>
    <axis xyz="0 0 1"/>
    <limit effort="0" lower="-3.1415926" upper="3.1415926" velocity="0"/>
  </joint> -->
</robot>