<?xml version="1.0" encoding="utf-8"?>
<!-- This URDF was automatically created by SolidWorks to URDF Exporter! Originally created by Stephen Brawner (brawner@gmail.com) 
     Commit Version: 1.6.0-4-g7f85cfe  Build Version: 1.6.7995.38578
     For more information, please see http://wiki.ros.org/sw_urdf_exporter -->
<robot
  name="serial_head">
  <link
    name="base_head_link">
    <inertial>
      <origin
        xyz="0.0176476882951905 -8.56421589775433E-05 -0.168668625147431"
        rpy="0 0 0" />
      <mass
        value="4.49480123992562" />
      <inertia
        ixx="0.0980145899657877"
        ixy="-8.79282303329283E-07"
        ixz="0.000155634090206416"
        iyy="0.0737342364326198"
        iyz="6.32223374315109E-05"
        izz="0.0269152816506406" />
    </inertial>
    <visual>
      <origin
        xyz="0 0 0"
        rpy="0 0 0" />
      <geometry>
        <mesh
          filename="package://head_planning/meshes/base_head_link.STL" />
      </geometry>
      <material
        name="">
        <color
          rgba="0.752941176470588 0.752941176470588 0.752941176470588 1" />
      </material>
    </visual>
    <collision>
      <origin
        xyz="0 0 0"
        rpy="0 0 0" />
      <geometry>
        <mesh
          filename="package://head_planning/meshes/base_head_link.STL" />
      </geometry>
    </collision>
  </link>
  <link
    name="yaw_Link">
    <inertial>
      <origin
        xyz="-4.00405706160734E-08 0.00932739380155157 0.0198358520856564"
        rpy="0 0 0" />
      <mass
        value="0.0453480116066019" />
      <inertia
        ixx="1.81587134930348E-05"
        ixy="7.62071763869279E-11"
        ixz="-2.69977569701655E-13"
        iyy="1.28755894444541E-05"
        iyz="3.54032720681978E-06"
        izz="1.37364417884893E-05" />
    </inertial>
    <visual>
      <origin
        xyz="0 0 0"
        rpy="0 0 0" />
      <geometry>
        <mesh
          filename="package://head_planning/meshes/yaw_Link.STL" />
      </geometry>
      <material
        name="">
        <color
          rgba="0.752941176470588 0.752941176470588 0.752941176470588 1" />
      </material>
    </visual>
    <collision>
      <origin
        xyz="0 0 0"
        rpy="0 0 0" />
      <geometry>
        <mesh
          filename="package://head_planning/meshes/yaw_Link.STL" />
      </geometry>
    </collision>
  </link>
  <joint
    name="yaw"
    type="continuous">
    <origin
      xyz="0 0 0.087"
      rpy="0 0 0" />
    <parent
      link="base_head_link" />
    <child
      link="yaw_Link" />
    <axis
      xyz="0 0 -1" />
  </joint>
  <link
    name="pitch_Link">
    <inertial>
      <origin
        xyz="0.00081735170886945 0.00664513729308302 0.000290176175041679"
        rpy="0 0 0" />
      <mass
        value="0.190759169196296" />
      <inertia
        ixx="4.60761752741039E-05"
        ixy="-1.2578979528302E-07"
        ixz="-2.52099013565467E-09"
        iyy="9.28648728027694E-05"
        iyz="1.50632133037674E-10"
        izz="5.7693405230162E-05" />
    </inertial>
    <visual>
      <origin
        xyz="0 0 0"
        rpy="0 0 0" />
      <geometry>
        <mesh
          filename="package://head_planning/meshes/pitch_Link.STL" />
      </geometry>
      <material
        name="">
        <color
          rgba="0.752941176470588 0.752941176470588 0.752941176470588 1" />
      </material>
    </visual>
    <collision>
      <origin
        xyz="0 0 0"
        rpy="0 0 0" />
      <geometry>
        <mesh
          filename="package://head_planning/meshes/pitch_Link.STL" />
      </geometry>
    </collision>
  </link>
  <joint
    name="pitch"
    type="continuous">
    <origin
      xyz="0 0 0.043"
      rpy="0 0 0" />
    <parent
      link="yaw_Link" />
    <child
      link="pitch_Link" />
    <axis
      xyz="0 1 0" />
  </joint>
  <link
    name="roll_Link">
    <inertial>
      <origin
        xyz="0.0298585803039214 -0.000196220658598675 0.0720776377693058"
        rpy="0 0 0" />
      <mass
        value="0.455178749739777" />
      <inertia
        ixx="0.000421705188552628"
        ixy="5.72481413372519E-07"
        ixz="7.36912864320739E-05"
        iyy="0.000316277158968809"
        iyz="2.79633005260355E-07"
        izz="0.000373294710993479" />
    </inertial>
    <visual>
      <origin
        xyz="0 0 0"
        rpy="0 0 0" />
      <geometry>
        <mesh
          filename="package://head_planning/meshes/roll_Link.STL" />
      </geometry>
      <material
        name="">
        <color
          rgba="0.752941176470588 0.752941176470588 0.752941176470588 1" />
      </material>
    </visual>
    <collision>
      <origin
        xyz="0 0 0"
        rpy="0 0 0" />
      <geometry>
        <mesh
          filename="package://head_planning/meshes/roll_Link.STL" />
      </geometry>
    </collision>
  </link>
  <joint
    name="roll"
    type="continuous">
    <origin
      xyz="0 0 0"
      rpy="0 0 0" />
    <parent
      link="pitch_Link" />
    <child
      link="roll_Link" />
    <axis
      xyz="-1 0 0" />
  </joint>
  <!-- <link
    name="camera_link">
    <inertial>
      <origin
        xyz="-0.031096602252572 -0.0177762297813027 -0.00195863567981297"
        rpy="0 0 0" />
      <mass
        value="0.167746208321735" />
      <inertia
        ixx="9.1351317754009E-05"
        ixy="-2.11129616864509E-08"
        ixz="-8.90534537142055E-06"
        iyy="5.77323787656724E-05"
        iyz="-6.85361413662525E-10"
        izz="0.000129617281110124" />
    </inertial>
    <visual>
      <origin
        xyz="0 0 0"
        rpy="0 0 0" />
      <geometry>
        <mesh
          filename="package://head_planning/meshes/camera_link.STL" />
      </geometry>
      <material
        name="">
        <color
          rgba="0.752941176470588 0.752941176470588 0.752941176470588 1" />
      </material>
    </visual>
    <collision>
      <origin
        xyz="0 0 0"
        rpy="0 0 0" />
      <geometry>
        <mesh
          filename="package://head_planning/meshes/camera_link.STL" />
      </geometry>
    </collision>
  </link>
  <joint
    name="head_camera"
    type="continuous">
    <origin
      xyz="0.0941645778356877 0.0174623935367009 0.0639892570623322"
      rpy="2.18166156499292 0 1.5707963267949" />
    <parent
      link="roll_Link" />
    <child
      link="camera_link" />
    <axis
      xyz="1 0 0" />
  </joint> -->
</robot>