<?xml version="1.0" encoding="utf-8"?>
<!-- This URDF was automatically created by SolidWorks to URDF Exporter! Originally created by Stephen Brawner (brawner@gmail.com) 
     Commit Version: 1.6.0-4-g7f85cfe  Build Version: 1.6.7995.38578
     For more information, please see http://wiki.ros.org/sw_urdf_exporter -->
<robot
  name="humanoid">
  <link
    name="base_link">
    <inertial>
      <origin
        xyz="-0.05335 0.0 -0.01884"
        rpy="0 0 0" />
      <mass
        value="4.73857" />
      <inertia
        ixx="0.10123"
        ixy="0.0"
        ixz="0.00416"
        iyy="0.02056"
        iyz="0.0"
        izz="0.10991" />
    </inertial>
    <visual>
      <origin
        xyz="0 0 0"
        rpy="0 0 0" />
      <geometry>
        <mesh
          filename="package://arm_kinematics_solver/meshes/base_link.STL" />
      </geometry>
      <material
        name="">
        <color
          rgba="0.752941176470588 0.752941176470588 0.752941176470588 1" />
      </material>
    </visual>
    <collision>
      <origin
        xyz="0 0 0"
        rpy="0 0 0" />
      <geometry>
        <mesh
          filename="package://arm_kinematics_solver/meshes/base_link.STL" />
      </geometry>
    </collision>
  </link>
  <link
    name="L-Roll-hip">
    <inertial>
      <origin
        xyz="-0.00045 0.00101 -0.02429"
        rpy="0 0 0" />
      <mass
        value="1.09852" />
      <inertia
        ixx="0.00132"
        ixy="0.0"
        ixz="-0.00001"
        iyy="0.00182"
        iyz="-0.00005"
        izz="0.00212" />
    </inertial>
    <visual>
      <origin
        xyz="0 0 0"
        rpy="0 0 0" />
      <geometry>
        <mesh
          filename="package://arm_kinematics_solver/meshes/L-Roll-hip.STL" />
      </geometry>
      <material
        name="">
        <color
          rgba="0.752941176470588 0.752941176470588 0.752941176470588 1" />
      </material>
    </visual>
    <collision>
      <origin
        xyz="0 0 0"
        rpy="0 0 0" />
      <geometry>
        <mesh
          filename="package://arm_kinematics_solver/meshes/L-Roll-hip.STL" />
      </geometry>
    </collision>
  </link>
  <joint
    name="L-Roll-hip"
    type="revolute">
    <origin
      xyz="0 0.15 -0.0375"
      rpy="0 0 0" />
    <parent
      link="base_link" />
    <child
      link="L-Roll-hip" />
    <axis
      xyz="1 0 0" />
    <limit effort="1000" lower="-3.14" upper="3.14" velocity="100"/>
    <dynamics damping="0.001" friction="0.001"/> 
   <dynamics damping="1.1" friction="1.5"/>
</joint>
  <link
    name="L-Yaw-hip">
    <inertial>
      <origin
        xyz="-0.00026 -0.00288 0.00358"
        rpy="0 0 0" />
      <mass
        value="3.36443" />
      <inertia
        ixx="0.01280"
        ixy="0.00004"
        ixz="0.00001"
        iyy="0.00722"
        iyz="-0.00011"
        izz="0.01238" />
    </inertial>
    <visual>
      <origin
        xyz="0 0 0"
        rpy="0 0 0" />
      <geometry>
        <mesh
          filename="package://arm_kinematics_solver/meshes/L-Yaw-hip.STL" />
      </geometry>
      <material
        name="">
        <color
          rgba="0.752941176470588 0.752941176470588 0.752941176470588 1" />
      </material>
    </visual>
    <collision>
      <origin
        xyz="0 0 0"
        rpy="0 0 0" />
      <geometry>
        <mesh
          filename="package://arm_kinematics_solver/meshes/L-Yaw-hip.STL" />
      </geometry>
    </collision>
  </link>
  <joint
    name="L-Yaw-hip"
    type="revolute">
    <origin
      xyz="0 0 -0.132"
      rpy="0 0 0" />
    <parent
      link="L-Roll-hip" />
    <child
      link="L-Yaw-hip" />
    <axis
      xyz="0 0 1" />
    <limit effort="1000" lower="-3.14" upper="3.14" velocity="100"/>
    <dynamics damping="0.001" friction="0.001"/> 
   <dynamics damping="1.1" friction="1.5"/>
</joint>
  <link
    name="L-Pitch-hip">
    <inertial>
      <origin
        xyz="-0.00022 0.00397 -0.21383"
        rpy="0 0 0" />
      <mass
        value="4.39844" />
      <inertia
        ixx="0.07048"
        ixy="0.00001"
        ixz="-0.00169"
        iyy="0.06296"
        iyz="0.00367"
        izz="0.01550" />
    </inertial>
    <visual>
      <origin
        xyz="0 0 0"
        rpy="0 0 0" />
      <geometry>
        <mesh
          filename="package://arm_kinematics_solver/meshes/L-Pitch-hip.STL" />
      </geometry>
      <material
        name="">
        <color
          rgba="0.752941176470588 0.752941176470588 0.752941176470588 1" />
      </material>
    </visual>
    <collision>
      <origin
        xyz="0 0 0"
        rpy="0 0 0" />
      <geometry>
        <mesh
          filename="package://arm_kinematics_solver/meshes/L-Pitch-hip.STL" />
      </geometry>
    </collision>
  </link>
  <joint
    name="L-Pitch-hip"
    type="revolute">
    <origin
      xyz="0 0 0"
      rpy="0 0 0" />
    <parent
      link="L-Yaw-hip" />
    <child
      link="L-Pitch-hip" />
    <axis
      xyz="0 1 0" />
    <limit effort="1000" lower="-3.14" upper="3.14" velocity="100"/>
    <dynamics damping="0.001" friction="0.001"/> 
   <dynamics damping="1.1" friction="1.5"/>
</joint>
  <link
    name="L-Pitch-knee">
    <inertial>
      <origin
        xyz="0.00412 -0.00005 -0.15111"
        rpy="0 0 0" />
      <mass
        value="1.46387" />
      <inertia
        ixx="0.01638"
        ixy="0.0"
        ixz="0.00259"
        iyy="0.01653"
        iyz="-0.00001"
        izz="0.00282" />
    </inertial>
    <visual>
      <origin
        xyz="0 0 0"
        rpy="0 0 0" />
      <geometry>
        <mesh
          filename="package://arm_kinematics_solver/meshes/L-Pitch-knee.STL" />
      </geometry>
      <material
        name="">
        <color
          rgba="0.752941176470588 0.752941176470588 0.752941176470588 1" />
      </material>
    </visual>
    <collision>
      <origin
        xyz="0 0 0"
        rpy="0 0 0" />
      <geometry>
        <mesh
          filename="package://arm_kinematics_solver/meshes/L-Pitch-knee.STL" />
      </geometry>
    </collision>
  </link>
  <joint
    name="L-Pitch-knee"
    type="revolute">
    <origin
      xyz="0 0 -0.3"
      rpy="0 0 0" />
    <parent
      link="L-Pitch-hip" />
    <child
      link="L-Pitch-knee" />
    <axis
      xyz="0 1 0" />
    <limit effort="1000" lower="-3.14" upper="3.14" velocity="100"/>
    <dynamics damping="0.001" friction="0.001"/> 
   <dynamics damping="1.1" friction="1.5"/>
</joint>
  <link
    name="L-Pitch-ankle">
    <inertial>
      <origin
        xyz="0.00027 0 0"
        rpy="0 0 0" />
      <mass
        value="0.15163" />
      <inertia
        ixx="0.00003"
        ixy="0"
        ixz="0"
        iyy="0.00003"
        iyz="0"
        izz="0.00006" />
    </inertial>
    <visual>
      <origin
        xyz="0 0 0"
        rpy="0 0 0" />
      <geometry>
        <mesh
          filename="package://arm_kinematics_solver/meshes/L-Pitch-ankle.STL" />
      </geometry>
      <material
        name="">
        <color
          rgba="0.752941176470588 0.752941176470588 0.752941176470588 1" />
      </material>
    </visual>
    <collision>
      <origin
        xyz="0 0 0"
        rpy="0 0 0" />
      <geometry>
        <mesh
          filename="package://arm_kinematics_solver/meshes/L-Pitch-ankle.STL" />
      </geometry>
    </collision>
  </link>
  <joint
    name="L-Pitch-ankle"
    type="revolute">
    <origin
      xyz="0 0 -0.3"
      rpy="0 0 0" />
    <parent
      link="L-Pitch-knee" />
    <child
      link="L-Pitch-ankle" />
    <axis
      xyz="0 1 0" />
    <limit effort="1000" lower="-3.14" upper="3.14" velocity="100"/>
    <dynamics damping="0.001" friction="0.001"/> 
   <dynamics damping="1.1" friction="1.5"/>
</joint>
  <link
    name="L-Roll-ankle">
    <inertial>
      <origin
        xyz="-0.01149 -0.00001 -0.03039"
        rpy="0 0 0" />
      <mass
        value="1.03585" />
      <inertia
        ixx="0.00133"
        ixy="0.0"
        ixz="-0.00047"
        iyy="0.00385"
        iyz="0.0"
        izz="0.00453" />
    </inertial>
    <visual>
      <origin
        xyz="0 0 0"
        rpy="0 0 0" />
      <geometry>
        <mesh
          filename="package://arm_kinematics_solver/meshes/L-Roll-ankle.STL" />
      </geometry>
      <material
        name="">
        <color
          rgba="0.752941176470588 0.752941176470588 0.752941176470588 1" />
      </material>
    </visual>
    <collision>
      <origin
        xyz="0 0 0"
        rpy="0 0 0" />
      <geometry>
        <mesh
          filename="package://arm_kinematics_solver/meshes/L-Roll-ankle.STL" />
      </geometry>
    </collision>
  </link>
  <joint
    name="L-Roll-ankle"
    type="revolute">
    <origin
      xyz="0 0 0"
      rpy="0 0 0" />
    <parent
      link="L-Pitch-ankle" />
    <child
      link="L-Roll-ankle" />
    <axis
      xyz="1 0 0" />
    <limit effort="1000" lower="-3.14" upper="3.14" velocity="100"/>
    <dynamics damping="0.001" friction="0.001"/> 
   <dynamics damping="1.1" friction="1.5"/>
</joint>
  <link
    name="R-Roll-hip">
    <inertial>
      <origin
        xyz="-0.00045 -0.00101 -0.02429"
        rpy="0 0 0" />
      <mass
        value="1.09852" />
      <inertia
        ixx="0.00132"
        ixy="0.0"
        ixz="-0.00001"
        iyy="0.00182"
        iyz="0.00005"
        izz="0.00212" />
    </inertial>
    <visual>
      <origin
        xyz="0 0 0"
        rpy="0 0 0" />
      <geometry>
        <mesh
          filename="package://arm_kinematics_solver/meshes/R-Roll-hip.STL" />
      </geometry>
      <material
        name="">
        <color
          rgba="0.752941176470588 0.752941176470588 0.752941176470588 1" />
      </material>
    </visual>
    <collision>
      <origin
        xyz="0 0 0"
        rpy="0 0 0" />
      <geometry>
        <mesh
          filename="package://arm_kinematics_solver/meshes/R-Roll-hip.STL" />
      </geometry>
    </collision>
  </link>
  <joint
    name="R-Roll-hip"
    type="revolute">
    <origin
      xyz="0 -0.15 -0.0375"
      rpy="0 0 0" />
    <parent
      link="base_link" />
    <child
      link="R-Roll-hip" />
    <axis
      xyz="1 0 0" />
    <limit effort="1000" lower="-3.14" upper="3.14" velocity="100"/>
    <dynamics damping="0.001" friction="0.001"/> 
   <dynamics damping="1.1" friction="1.5"/>
</joint>
  <link
    name="R-Yaw-hip">
    <inertial>
      <origin
        xyz="-0.00026 0.00288 0.00358"
        rpy="0 0 0" />
      <mass
        value="3.36443" />
      <inertia
        ixx="0.01280"
        ixy="-0.00004"
        ixz="0.00001"
        iyy="0.00722"
        iyz="0.00011"
        izz="0.01238" />
    </inertial>
    <visual>
      <origin
        xyz="0 0 0"
        rpy="0 0 0" />
      <geometry>
        <mesh
          filename="package://arm_kinematics_solver/meshes/R-Yaw-hip.STL" />
      </geometry>
      <material
        name="">
        <color
          rgba="0.752941176470588 0.752941176470588 0.752941176470588 1" />
      </material>
    </visual>
    <collision>
      <origin
        xyz="0 0 0"
        rpy="0 0 0" />
      <geometry>
        <mesh
          filename="package://arm_kinematics_solver/meshes/R-Yaw-hip.STL" />
      </geometry>
    </collision>
  </link>
  <joint
    name="R-Yaw-hip"
    type="revolute">
    <origin
      xyz="0 0 -0.132"
      rpy="0 0 0" />
    <parent
      link="R-Roll-hip" />
    <child
      link="R-Yaw-hip" />
    <axis
      xyz="0 0 1" />
    <limit effort="1000" lower="-3.14" upper="3.14" velocity="100"/>
    <dynamics damping="0.001" friction="0.001"/> 
   <dynamics damping="1.1" friction="1.5"/>
</joint>
  <link
    name="R-Pitch-hip">
    <inertial>
      <origin
        xyz="-0.00022 -0.00397 -0.21383"
        rpy="0 0 0" />
      <mass
        value="4.39844" />
      <inertia
        ixx="0.07048"
        ixy="-0.00001"
        ixz="-0.00169"
        iyy="0.06296"
        iyz="-0.00367"
        izz="0.01550" />
    </inertial>
    <visual>
      <origin
        xyz="0 0 0"
        rpy="0 0 0" />
      <geometry>
        <mesh
          filename="package://arm_kinematics_solver/meshes/R-Pitch-hip.STL" />
      </geometry>
      <material
        name="">
        <color
          rgba="0.752941176470588 0.752941176470588 0.752941176470588 1" />
      </material>
    </visual>
    <collision>
      <origin
        xyz="0 0 0"
        rpy="0 0 0" />
      <geometry>
        <mesh
          filename="package://arm_kinematics_solver/meshes/R-Pitch-hip.STL" />
      </geometry>
    </collision>
  </link>
  <joint
    name="R-Pitch-hip"
    type="revolute">
    <origin
      xyz="0 0 0"
      rpy="0 0 0" />
    <parent
      link="R-Yaw-hip" />
    <child
      link="R-Pitch-hip" />
    <axis
      xyz="0 1 0" />
    <limit effort="1000" lower="-3.14" upper="3.14" velocity="100"/>
    <dynamics damping="0.001" friction="0.001"/> 
   <dynamics damping="1.1" friction="1.5"/>
</joint>
  <link
    name="R-Pitch-knee">
    <inertial>
      <origin
        xyz="0.00412 0.00005 -0.15111"
        rpy="0 0 0" />
      <mass
        value="1.46387" />
      <inertia
        ixx="0.01638"
        ixy="0.0"
        ixz="0.00259"
        iyy="0.01653"
        iyz="0.00001"
        izz="0.00282" />
    </inertial>
    <visual>
      <origin
        xyz="0 0 0"
        rpy="0 0 0" />
      <geometry>
        <mesh
          filename="package://arm_kinematics_solver/meshes/R-Pitch-knee.STL" />
      </geometry>
      <material
        name="">
        <color
          rgba="0.752941176470588 0.752941176470588 0.752941176470588 1" />
      </material>
    </visual>
    <collision>
      <origin
        xyz="0 0 0"
        rpy="0 0 0" />
      <geometry>
        <mesh
          filename="package://arm_kinematics_solver/meshes/R-Pitch-knee.STL" />
      </geometry>
    </collision>
  </link>
  <joint
    name="R-Pitch-knee"
    type="revolute">
    <origin
      xyz="0 0 -0.3"
      rpy="0 0 0" />
    <parent
      link="R-Pitch-hip" />
    <child
      link="R-Pitch-knee" />
    <axis
      xyz="0 1 0" />
    <limit effort="1000" lower="-3.14" upper="3.14" velocity="100"/>
    <dynamics damping="0.001" friction="0.001"/> 
   <dynamics damping="1.1" friction="1.5"/>
</joint>
  <link
    name="R-Pitch-ankle">
    <inertial>
      <origin
        xyz="0.00027 0.0 0.0"
        rpy="0 0 0" />
      <mass
        value="0.15163" />
      <inertia
        ixx="0.00003"
        ixy="0.0"
        ixz="0.0"
        iyy="0.00003"
        iyz="0.0"
        izz="0.00006" />
    </inertial>
    <visual>
      <origin
        xyz="0 0 0"
        rpy="0 0 0" />
      <geometry>
        <mesh
          filename="package://arm_kinematics_solver/meshes/R-Pitch-ankle.STL" />
      </geometry>
      <material
        name="">
        <color
          rgba="0.752941176470588 0.752941176470588 0.752941176470588 1" />
      </material>
    </visual>
    <collision>
      <origin
        xyz="0 0 0"
        rpy="0 0 0" />
      <geometry>
        <mesh
          filename="package://arm_kinematics_solver/meshes/R-Pitch-ankle.STL" />
      </geometry>
    </collision>
  </link>
  <joint
    name="R-Pitch-ankle"
    type="revolute">
    <origin
      xyz="0 0 -0.3"
      rpy="0 0 0" />
    <parent
      link="R-Pitch-knee" />
    <child
      link="R-Pitch-ankle" />
    <axis
      xyz="0 1 0" />
    <limit effort="1000" lower="-3.14" upper="3.14" velocity="100"/>
    <dynamics damping="0.001" friction="0.001"/> 
   <dynamics damping="1.1" friction="1.5"/>
</joint>
  <link
    name="R-Roll-ankle">
    <inertial>
      <origin
        xyz="-0.01149 0.00001 -0.03039"
        rpy="0 0 0" />
      <mass
        value="1.03585" />
      <inertia
        ixx="0.00133"
        ixy="0.0"
        ixz="-0.00047"
        iyy="0.00385"
        iyz="0.0"
        izz="0.00453" />
    </inertial>
    <visual>
      <origin
        xyz="0 0 0"
        rpy="0 0 0" />
      <geometry>
        <mesh
          filename="package://arm_kinematics_solver/meshes/R-Roll-ankle.STL" />
      </geometry>
      <material
        name="">
        <color
          rgba="0.752941176470588 0.752941176470588 0.752941176470588 1" />
      </material>
    </visual>
    <collision>
      <origin
        xyz="0 0 0"
        rpy="0 0 0" />
      <geometry>
        <mesh
          filename="package://arm_kinematics_solver/meshes/R-Roll-ankle.STL" />
      </geometry>
    </collision>
  </link>
  <joint
    name="R-Roll-ankle"
    type="revolute">
    <origin
      xyz="0 0 0"
      rpy="0 0 0" />
    <parent
      link="R-Pitch-ankle" />
    <child
      link="R-Roll-ankle" />
    <axis
      xyz="1 0 0" />
    <limit effort="1000" lower="-3.14" upper="3.14" velocity="100"/>
    <dynamics damping="0.001" friction="0.001"/> 
   <dynamics damping="1.1" friction="1.5"/>
</joint>
  <link
    name="WAIST">
    <inertial>
      <origin
        xyz="0.009595 0.0 0.266449"
        rpy="0 0 0" />
      <mass
        value="13.646946" />
      <inertia
        ixx="0.441452"
        ixy="-0.000549"
        ixz="0.017287"
        iyy="0.367799"
        iyz="0.001135"
        izz="0.157351" />
    </inertial>
    <visual>
      <origin
        xyz="0 0 0"
        rpy="0 0 0" />
      <geometry>
        <mesh
          filename="package://arm_kinematics_solver/meshes/WAIST.STL" />
      </geometry>
      <material
        name="">
        <color
          rgba="0.752941176470588 0.752941176470588 0.752941176470588 1" />
      </material>
    </visual>
    <collision>
      <origin
        xyz="0 0 0"
        rpy="0 0 0" />
      <geometry>
        <mesh
          filename="package://arm_kinematics_solver/meshes/WAIST.STL" />
      </geometry>
    </collision>
  </link>
  <joint
    name="WAIST"
    type="revolute">
    <origin
      xyz="0 0 0.0192"
      rpy="0 0 0" />
    <parent
      link="base_link" />
    <child
      link="WAIST" />
    <axis
      xyz="0 0 1" />
    <limit effort="1000" lower="-3.14" upper="3.14" velocity="100"/>
    <dynamics damping="0.001" friction="0.001"/> 
   <dynamics damping="1.1" friction="1.5"/>
</joint>
  <link name="left_base_link">
    <inertial>
      <origin rpy="0 0 0" xyz="-0.00076435 -6.5733E-05 0.053673"/>
      <mass value="1.000918"/>
      <inertia ixx="0.000829" ixy="0.000001" ixz="0.000034" iyy="0.000843" iyz="0.000003" izz="0.000621"/>
    </inertial>
    <visual>
      <origin rpy="0 0 0" xyz="0 0 0"/>
      <geometry>
        <mesh filename="package://arm_kinematics_solver/meshes/arm_base_link.STL"/>
      </geometry>
      <material name="">
        <color rgba="0.79216 0.81961 0.93333 1"/>
      </material>
    </visual>
  </link>
  <joint
    name="left_fixed_joint"
    type="fixed">
    <origin
      xyz="0 0.14632 0.414"
      rpy="-1.308997 0 0" />
    <parent
      link="WAIST" />
    <child
      link="left_base_link" />
    <axis
      xyz="0 1 0" />
   <dynamics damping="1.1" friction="1.5"/>
</joint>
  <link name="left_Link1">
    <inertial>
      <origin rpy="0 0 0" xyz="-5.2554E-05 -0.0053442 -0.0082759"/>
      <mass value="1.301479"/>
      <inertia ixx="0.001955" ixy="-0.000003" ixz="-0.000002" iyy="0.001633" iyz="-0.000034" izz="0.001269"/>
    </inertial>
    <visual>
      <origin rpy="0 0 0" xyz="0 0 0"/>
      <geometry>
        <mesh filename="package://arm_kinematics_solver/meshes/Link1.STL"/>
      </geometry>
      <material name="">
        <color rgba="0.79216 0.81961 0.93333 1"/>
      </material>
    </visual>
    <collision>
      <origin rpy="0 0 0" xyz="0 0 0"/>
      <geometry>
        <mesh filename="package://arm_kinematics_solver/meshes/Link1.STL"/>
      </geometry>
    </collision>
  </link>
  <joint name="left_joint1" type="revolute">
    <origin rpy="0 0 0" xyz="0 0 0.182"/>
    <parent link="left_base_link"/>
    <child link="left_Link1"/>
    <axis xyz="0 0 1"/>
    <limit effort="0" lower="-3.1415926" upper="3.1415926" velocity="0"/>
   <dynamics damping="1.1" friction="1.5"/>
</joint>
  <link name="left_Link2">
    <inertial>
      <origin rpy="0 0 0" xyz="0.00025764 -0.094316 0.00044678"/>
      <mass value="1.191673"/>
      <inertia ixx="0.003751" ixy="0.000005" ixz="0.000003" iyy="0.001170" iyz="0.000117" izz="0.003283"/>
    </inertial>
    <visual>
      <origin rpy="0 0 0" xyz="0 0 0"/>
      <geometry>
        <mesh filename="package://arm_kinematics_solver/meshes/Link2.STL"/>
      </geometry>
      <material name="">
        <color rgba="0.79216 0.81961 0.93333 1"/>
      </material>
    </visual>
    <collision>
      <origin rpy="0 0 0" xyz="0 0 0"/>
      <geometry>
        <mesh filename="package://arm_kinematics_solver/meshes/Link2.STL"/>
      </geometry>
    </collision>
  </link>
  <joint name="left_joint2" type="revolute">
    <origin rpy="-1.5707963267948966 0 0" xyz="0 0 0"/>
    <parent link="left_Link1"/>
    <child link="left_Link2"/>
    <axis xyz="0 0 1"/>
    <limit effort="0" lower="-2.18" upper="2.18" velocity="0"/>
   <dynamics damping="1.1" friction="1.5"/>
</joint>
  <link name="left_Link3">
    <inertial>
      <origin rpy="0 0 0" xyz="0.00031625 -0.0039156 -0.012819"/>
      <mass value="1.004294"/>
      <inertia ixx="0.001754" ixy="0.000012" ixz="0.000008" iyy="0.001475" iyz="-0.000039" izz="0.000839"/>
    </inertial>
    <visual>
      <origin rpy="0 0 0" xyz="0 0 0"/>
      <geometry>
        <mesh filename="package://arm_kinematics_solver/meshes/Link3.STL"/>
      </geometry>
      <material name="">
        <color rgba="0.79216 0.81961 0.93333 1"/>
      </material>
    </visual>
    <collision>
      <origin rpy="0 0 0" xyz="0 0 0"/>
      <geometry>
        <mesh filename="package://arm_kinematics_solver/meshes/Link3.STL"/>
      </geometry>
    </collision>
  </link>
  <joint name="left_joint3" type="revolute">
    <origin rpy="1.5707963267948966 0 0" xyz="0 -0.276 0"/>
    <parent link="left_Link2"/>
    <child link="left_Link3"/>
    <axis xyz="0 0 1"/>
    <limit effort="0" lower="-3.1415926" upper="3.1415926" velocity="0"/>
   <dynamics damping="1.1" friction="1.5"/>
</joint>
  <link name="left_Link4">
    <inertial>
      <origin rpy="0 0 0" xyz="9.892E-06 -0.075751 3.1247E-05"/>
      <mass value="0.725811"/>
      <inertia ixx="0.001959" ixy="-0.000001" ixz="0.000000" iyy="0.000660" iyz="0.000072" izz="0.001613"/>
    </inertial>
    <visual>
      <origin rpy="0 0 0" xyz="0 0 0"/>
      <geometry>
        <mesh filename="package://arm_kinematics_solver/meshes/Link4.STL"/>
      </geometry>
      <material name="">
        <color rgba="0.79216 0.81961 0.93333 1"/>
      </material>
    </visual>
    <collision>
      <origin rpy="0 0 0" xyz="0 0 0"/>
      <geometry>
        <mesh filename="package://arm_kinematics_solver/meshes/Link4.STL"/>
      </geometry>
    </collision>
  </link>
  <joint name="left_joint4" type="revolute">
    <origin rpy="-1.5707963267948966 0 0" xyz="0 0 0"/>
    <parent link="left_Link3"/>
    <child link="left_Link4"/>
    <axis xyz="0 0 1"/>
    <limit effort="0" lower="-2.14" upper="2.14" velocity="0"/>
   <dynamics damping="1.1" friction="1.5"/>
</joint>
  <link name="left_Link5">
    <inertial>
      <origin rpy="0 0 0" xyz="-3.8461E-06 0.0019832 -0.076384"/>
      <mass value="0.729280"/>
      <inertia ixx="0.001311" ixy="0.000000" ixz="0.000000" iyy="0.000991" iyz="0.000041" izz="0.000605"/>
    </inertial>
    <visual>
      <origin rpy="0 0 0" xyz="0 0 0"/>
      <geometry>
        <mesh filename="package://arm_kinematics_solver/meshes/Link5.STL"/>
      </geometry>
      <material name="">
        <color rgba="0.79216 0.81961 0.93333 1"/>
      </material>
    </visual>
    <collision>
      <origin rpy="0 0 0" xyz="0 0 0"/>
      <geometry>
        <mesh filename="package://arm_kinematics_solver/meshes/Link5.STL"/>
      </geometry>
    </collision>
  </link>
  <joint name="left_joint5" type="revolute">
    <origin rpy="1.5707963267948966 0 0" xyz="0 -0.28 0"/>
    <parent link="left_Link4"/>
    <child link="left_Link5"/>
    <axis xyz="0 0 1"/>
    <limit effort="0" lower="-3.1415926" upper="3.1415926" velocity="0"/>
   <dynamics damping="1.1" friction="1.5"/>
</joint>
  <link name="left_Link6">
    <inertial>
      <origin rpy="0 0 0" xyz="-1.8651E-05 -0.0033108 -0.0014235"/>
      <mass value="0.476825"/>
      <inertia ixx="0.000271" ixy="0.000000" ixz="-0.000003" iyy="0.000199" iyz="-0.000003" izz="0.000234"/>
    </inertial>
    <visual>
      <origin rpy="0 0 0" xyz="0 0 0"/>
      <geometry>
        <mesh filename="package://arm_kinematics_solver/meshes/Link6.STL"/>
      </geometry>
      <material name="">
        <color rgba="0.79216 0.81961 0.93333 1"/>
      </material>
    </visual>
    <collision>
      <origin rpy="0 0 0" xyz="0 0 0"/>
      <geometry>
        <mesh filename="package://arm_kinematics_solver/meshes/Link6.STL"/>
      </geometry>
    </collision>
  </link>
  <joint name="left_joint6" type="revolute">
    <origin rpy="-1.5707963267948966 0 0" xyz="0 0 0"/>
    <parent link="left_Link5"/>
    <child link="left_Link6"/>
    <axis xyz="0 0 1"/>
    <limit effort="0" lower="-1.57" upper="1.57" velocity="0"/>
   <dynamics damping="1.1" friction="1.5"/>
</joint>
  <link name="left_Link7">
    <inertial>
      <origin rpy="0 0 0" xyz="-1.3476E-07 -9.8969E-08 -0.0077909"/>
      <mass value="0.035040"/>
      <inertia ixx="0.000011" ixy="0.000000" ixz="0.000000" iyy="0.000011" iyz="0.000000" izz="0.000020"/>
    </inertial>
    <visual>
      <origin rpy="0 0 0" xyz="0 0 0"/>
      <geometry>
        <mesh filename="package://arm_kinematics_solver/meshes/Link7.STL"/>
      </geometry>
      <material name="">
        <color rgba="0.79216 0.81961 0.93333 1"/>
      </material>
    </visual>
    <collision>
      <origin rpy="0 0 0" xyz="0 0 0"/>
      <geometry>
        <mesh filename="package://arm_kinematics_solver/meshes/Link7.STL"/>
      </geometry>
    </collision>
  </link>
  <joint name="left_joint7" type="revolute">
    <origin rpy="1.5707963267948966 0 0" xyz="0 -0.044 0"/>
    <parent link="left_Link6"/>
    <child link="left_Link7"/>
    <axis xyz="0 0 1"/>
    <limit effort="0" lower="-3.1415926" upper="3.1415926" velocity="0"/>
   <dynamics damping="1.1" friction="1.5"/>
</joint>

   <link name="right_base_link">
    <inertial>
      <origin rpy="0 0 0" xyz="-0.00076435 -6.5733E-05 0.053673"/>
      <mass value="1.000918"/>
      <inertia ixx="0.000829" ixy="0.000001" ixz="0.000034" iyy="0.000843" iyz="0.000003" izz="0.000621"/>
    </inertial>
    <visual>
      <origin rpy="0 0 0" xyz="0 0 0"/>
      <geometry>
        <mesh filename="package://arm_kinematics_solver/meshes/arm_base_link.STL"/>
      </geometry>
      <material name="">
        <color rgba="0.79216 0.81961 0.93333 1"/>
      </material>
    </visual>
    <collision>
      <origin rpy="0 0 0" xyz="0 0 0"/>
      <geometry>
        <mesh filename="package://arm_kinematics_solver/meshes/arm_base_link.STL"/>
      </geometry>
    </collision>
  </link>
  <joint
    name="right_fixed_joint"
    type="fixed">
    <origin
      xyz="0 -0.14632 0.414"
      rpy="1.308997 0 0" />
    <parent
      link="WAIST" />
    <child
      link="right_base_link" />
    <axis
      xyz="0 1 0" />
   <dynamics damping="1.1" friction="1.5"/>
</joint>
  <link name="right_Link1">
    <inertial>
      <origin rpy="0 0 0" xyz="-5.2554E-05 -0.0053442 -0.0082759"/>
      <mass value="1.301479"/>
      <inertia ixx="0.001955" ixy="-0.000003" ixz="-0.000002" iyy="0.001633" iyz="-0.000034" izz="0.001269"/>
    </inertial>
    <visual>
      <origin rpy="0 0 0" xyz="0 0 0"/>
      <geometry>
        <mesh filename="package://arm_kinematics_solver/meshes/Link1.STL"/>
      </geometry>
      <material name="">
        <color rgba="0.79216 0.81961 0.93333 1"/>
      </material>
    </visual>
    <collision>
      <origin rpy="0 0 0" xyz="0 0 0"/>
      <geometry>
        <mesh filename="package://arm_kinematics_solver/meshes/Link1.STL"/>
      </geometry>
    </collision>
  </link>
  <joint name="right_joint1" type="revolute">
    <origin rpy="0 0 0" xyz="0 0 0.182"/>
    <parent link="right_base_link"/>
    <child link="right_Link1"/>
    <axis xyz="0 0 1"/>
    <limit effort="0" lower="-3.1415926" upper="3.1415926" velocity="0"/>
   <dynamics damping="1.1" friction="1.5"/>
</joint>
  <link name="right_Link2">
    <inertial>
      <origin rpy="0 0 0" xyz="0.00025764 -0.094316 0.00044678"/>
      <mass value="1.191673"/>
      <inertia ixx="0.003751" ixy="0.000005" ixz="0.000003" iyy="0.001170" iyz="0.000117" izz="0.003283"/>
    </inertial>
    <visual>
      <origin rpy="0 0 0" xyz="0 0 0"/>
      <geometry>
        <mesh filename="package://arm_kinematics_solver/meshes/Link2.STL"/>
      </geometry>
      <material name="">
        <color rgba="0.79216 0.81961 0.93333 1"/>
      </material>
    </visual>
    <collision>
      <origin rpy="0 0 0" xyz="0 0 0"/>
      <geometry>
        <mesh filename="package://arm_kinematics_solver/meshes/Link2.STL"/>
      </geometry>
    </collision>
  </link>
  <joint name="right_joint2" type="revolute">
    <origin rpy="-1.5707963267948966 0 0" xyz="0 0 0"/>
    <parent link="right_Link1"/>
    <child link="right_Link2"/>
    <axis xyz="0 0 1"/>
    <limit effort="0" lower="-2.18" upper="2.18" velocity="0"/>
   <dynamics damping="1.1" friction="1.5"/>
</joint>
  <link name="right_Link3">
    <inertial>
      <origin rpy="0 0 0" xyz="0.00031625 -0.0039156 -0.012819"/>
      <mass value="1.004294"/>
      <inertia ixx="0.001754" ixy="0.000012" ixz="0.000008" iyy="0.001475" iyz="-0.000039" izz="0.000839"/>
    </inertial>
    <visual>
      <origin rpy="0 0 0" xyz="0 0 0"/>
      <geometry>
        <mesh filename="package://arm_kinematics_solver/meshes/Link3.STL"/>
      </geometry>
      <material name="">
        <color rgba="0.79216 0.81961 0.93333 1"/>
      </material>
    </visual>
    <collision>
      <origin rpy="0 0 0" xyz="0 0 0"/>
      <geometry>
        <mesh filename="package://arm_kinematics_solver/meshes/Link3.STL"/>
      </geometry>
    </collision>
  </link>
  <joint name="right_joint3" type="revolute">
    <origin rpy="1.5707963267948966 0 0" xyz="0 -0.276 0"/>
    <parent link="right_Link2"/>
    <child link="right_Link3"/>
    <axis xyz="0 0 1"/>
    <limit effort="0" lower="-3.1415926" upper="3.1415926" velocity="0"/>
   <dynamics damping="1.1" friction="1.5"/>
</joint>
  <link name="right_Link4">
    <inertial>
      <origin rpy="0 0 0" xyz="9.892E-06 -0.075751 3.1247E-05"/>
      <mass value="0.725811"/>
      <inertia ixx="0.001959" ixy="-0.000001" ixz="0.000000" iyy="0.000660" iyz="0.000072" izz="0.001613"/>
    </inertial>
    <visual>
      <origin rpy="0 0 0" xyz="0 0 0"/>
      <geometry>
        <mesh filename="package://arm_kinematics_solver/meshes/Link4.STL"/>
      </geometry>
      <material name="">
        <color rgba="0.79216 0.81961 0.93333 1"/>
      </material>
    </visual>
    <collision>
      <origin rpy="0 0 0" xyz="0 0 0"/>
      <geometry>
        <mesh filename="package://arm_kinematics_solver/meshes/Link4.STL"/>
      </geometry>
    </collision>
  </link>
  <joint name="right_joint4" type="revolute">
    <origin rpy="-1.5707963267948966 0 0" xyz="0 0 0"/>
    <parent link="right_Link3"/>
    <child link="right_Link4"/>
    <axis xyz="0 0 1"/>
    <limit effort="0" lower="-2.14" upper="2.14" velocity="0"/>
   <dynamics damping="1.1" friction="1.5"/>
</joint>
  <link name="right_Link5">
    <inertial>
      <origin rpy="0 0 0" xyz="-3.8461E-06 0.0019832 -0.076384"/>
      <mass value="0.729280"/>
      <inertia ixx="0.001311" ixy="0.000000" ixz="0.000000" iyy="0.000991" iyz="0.000041" izz="0.000605"/>
    </inertial>
    <visual>
      <origin rpy="0 0 0" xyz="0 0 0"/>
      <geometry>
        <mesh filename="package://arm_kinematics_solver/meshes/Link5.STL"/>
      </geometry>
      <material name="">
        <color rgba="0.79216 0.81961 0.93333 1"/>
      </material>
    </visual>
    <collision>
      <origin rpy="0 0 0" xyz="0 0 0"/>
      <geometry>
        <mesh filename="package://arm_kinematics_solver/meshes/Link5.STL"/>
      </geometry>
    </collision>
  </link>
  <joint name="right_joint5" type="revolute">
    <origin rpy="1.5707963267948966 0 0" xyz="0 -0.28 0"/>
    <parent link="right_Link4"/>
    <child link="right_Link5"/>
    <axis xyz="0 0 1"/>
    <limit effort="0" lower="-3.1415926" upper="3.1415926" velocity="0"/>
   <dynamics damping="1.1" friction="1.5"/>
</joint>
  <link name="right_Link6">
    <inertial>
      <origin rpy="0 0 0" xyz="-1.8651E-05 -0.0033108 -0.0014235"/>
      <mass value="0.476825"/>
      <inertia ixx="0.000271" ixy="0.000000" ixz="-0.000003" iyy="0.000199" iyz="-0.000003" izz="0.000234"/>
    </inertial>
    <visual>
      <origin rpy="0 0 0" xyz="0 0 0"/>
      <geometry>
        <mesh filename="package://arm_kinematics_solver/meshes/Link6.STL"/>
      </geometry>
      <material name="">
        <color rgba="0.79216 0.81961 0.93333 1"/>
      </material>
    </visual>
    <collision>
      <origin rpy="0 0 0" xyz="0 0 0"/>
      <geometry>
        <mesh filename="package://arm_kinematics_solver/meshes/Link6.STL"/>
      </geometry>
    </collision>
  </link>
  <joint name="right_joint6" type="revolute">
    <origin rpy="-1.5707963267948966 0 0" xyz="0 0 0"/>
    <parent link="right_Link5"/>
    <child link="right_Link6"/>
    <axis xyz="0 0 1"/>
    <limit effort="0" lower="-1.57" upper="1.57" velocity="0"/>
   <dynamics damping="1.1" friction="1.5"/>
</joint>
  <link name="right_Link7">
    <inertial>
      <origin rpy="0 0 0" xyz="-1.3476E-07 -9.8969E-08 -0.0077909"/>
      <mass value="0.035040"/>
      <inertia ixx="0.000011" ixy="0.000000" ixz="0.000000" iyy="0.000011" iyz="0.000000" izz="0.000020"/>
    </inertial>
    <visual>
      <origin rpy="0 0 0" xyz="0 0 0"/>
      <geometry>
        <mesh filename="package://arm_kinematics_solver/meshes/Link7.STL"/>
      </geometry>
      <material name="">
        <color rgba="0.79216 0.81961 0.93333 1"/>
      </material>
    </visual>
    <collision>
      <origin rpy="0 0 0" xyz="0 0 0"/>
      <geometry>
        <mesh filename="package://arm_kinematics_solver/meshes/Link7.STL"/>
      </geometry>
    </collision>
  </link>
  <joint name="right_joint7" type="revolute">
    <origin rpy="1.5707963267948966 0 0" xyz="0 -0.044 0"/>
    <parent link="right_Link6"/>
    <child link="right_Link7"/>
    <axis xyz="0 0 1"/>
    <limit effort="0" lower="-3.1415926" upper="3.1415926" velocity="0"/>
   <dynamics damping="1.1" friction="1.5"/>
</joint>
</robot>